Traceback (most recent call last):
  File "C:\Users\tiopa\OneDrive\Documentos\GitHub\Projeto-01\sistema_previsao_acoes\venv\lib\site-packages\yfinance\multi.py", line 209, in download
    data = _pd.concat(shared._DFS.values(), axis=1, sort=True,
  File "C:\Users\tiopa\OneDrive\Documentos\GitHub\Projeto-01\sistema_previsao_acoes\venv\lib\site-packages\pandas\core\reshape\concat.py", line 382, in concat
    op = _Concatenator(
  File "C:\Users\tiopa\OneDrive\Documentos\GitHub\Projeto-01\sistema_previsao_acoes\venv\lib\site-packages\pandas\core\reshape\concat.py", line 445, in __init__
    objs, keys = self._clean_keys_and_objs(objs, keys)
  File "C:\Users\tiopa\OneDrive\Documentos\GitHub\Projeto-01\sistema_previsao_acoes\venv\lib\site-packages\pandas\core\reshape\concat.py", line 507, in _clean_keys_and_objs
    raise ValueError("No objects to concatenate")
ValueError: No objects to concatenate

During handling of the above exception, another exception occurred:

Traceback (most recent call last):
  File "c:\Users\tiopa\OneDrive\Documentos\GitHub\Projeto-01\sistema_previsao_acoes\previsao_acoes.py", line 17, in main
    dados = yf.download(ticker, start='2015-01-01', end='2023-12-31')
  File "C:\Users\tiopa\OneDrive\Documentos\GitHub\Projeto-01\sistema_previsao_acoes\venv\lib\site-packages\yfinance\utils.py", line 104, in wrapper
    result = func(*args, **kwargs)
  File "C:\Users\tiopa\OneDrive\Documentos\GitHub\Projeto-01\sistema_previsao_acoes\venv\lib\site-packages\yfinance\multi.py", line 213, in download
    data = _pd.concat(shared._DFS.values(), axis=1, sort=True,
  File "C:\Users\tiopa\OneDrive\Documentos\GitHub\Projeto-01\sistema_previsao_acoes\venv\lib\site-packages\pandas\core\reshape\concat.py", line 382, in concat
    op = _Concatenator(
  File "C:\Users\tiopa\OneDrive\Documentos\GitHub\Projeto-01\sistema_previsao_acoes\venv\lib\site-packages\pandas\core\reshape\concat.py", line 445, in __init__
    objs, keys = self._clean_keys_and_objs(objs, keys)
  File "C:\Users\tiopa\OneDrive\Documentos\GitHub\Projeto-01\sistema_previsao_acoes\venv\lib\site-packages\pandas\core\reshape\concat.py", line 507, in _clean_keys_and_objs
    raise ValueError("No objects to concatenate")
ValueError: No objects to concatenate
